2024-03-25 19:01:46,801 INFO    StreamThr :25780 [internal.py:wandb_internal():86] W&B internal server running at pid: 25780, started at: 2024-03-25 19:01:46.801500
2024-03-25 19:01:46,804 DEBUG   HandlerThread:25780 [handler.py:handle_request():146] handle_request: status
2024-03-25 19:01:46,807 INFO    WriterThread:25780 [datastore.py:open_for_write():87] open: C:\Shaurya\Longformer2\wandb\run-20240325_190146-bw3hnclm\run-bw3hnclm.wandb
2024-03-25 19:01:46,808 DEBUG   SenderThread:25780 [sender.py:send():378] send: header
2024-03-25 19:01:47,015 DEBUG   SenderThread:25780 [sender.py:send():378] send: run
2024-03-25 19:01:47,827 INFO    SenderThread:25780 [dir_watcher.py:__init__():211] watching files in: C:\Shaurya\Longformer2\wandb\run-20240325_190146-bw3hnclm\files
2024-03-25 19:01:47,827 INFO    SenderThread:25780 [sender.py:_start_run_threads():1099] run started: bw3hnclm with start time 1711373506.803583
2024-03-25 19:01:47,836 DEBUG   HandlerThread:25780 [handler.py:handle_request():146] handle_request: check_version
2024-03-25 19:01:47,837 DEBUG   SenderThread:25780 [sender.py:send_request():405] send_request: check_version
2024-03-25 19:01:47,983 DEBUG   HandlerThread:25780 [handler.py:handle_request():146] handle_request: run_start
2024-03-25 19:01:49,228 DEBUG   HandlerThread:25780 [system_info.py:__init__():26] System info init
2024-03-25 19:01:49,228 DEBUG   HandlerThread:25780 [system_info.py:__init__():41] System info init done
2024-03-25 19:01:49,228 INFO    HandlerThread:25780 [system_monitor.py:start():194] Starting system monitor
2024-03-25 19:01:49,228 INFO    SystemMonitor:25780 [system_monitor.py:_start():158] Starting system asset monitoring threads
2024-03-25 19:01:49,228 INFO    HandlerThread:25780 [system_monitor.py:probe():214] Collecting system info
2024-03-25 19:01:49,235 INFO    SystemMonitor:25780 [interfaces.py:start():190] Started cpu monitoring
2024-03-25 19:01:49,236 INFO    SystemMonitor:25780 [interfaces.py:start():190] Started disk monitoring
2024-03-25 19:01:49,237 INFO    SystemMonitor:25780 [interfaces.py:start():190] Started gpu monitoring
2024-03-25 19:01:49,243 INFO    SystemMonitor:25780 [interfaces.py:start():190] Started memory monitoring
2024-03-25 19:01:49,249 DEBUG   HandlerThread:25780 [system_info.py:probe():150] Probing system
2024-03-25 19:01:49,265 INFO    SystemMonitor:25780 [interfaces.py:start():190] Started network monitoring
2024-03-25 19:01:49,267 DEBUG   HandlerThread:25780 [system_info.py:_probe_git():135] Probing git
2024-03-25 19:01:49,376 DEBUG   HandlerThread:25780 [system_info.py:_probe_git():143] Probing git done
2024-03-25 19:01:49,376 DEBUG   HandlerThread:25780 [system_info.py:probe():198] Probing system done
2024-03-25 19:01:49,376 DEBUG   HandlerThread:25780 [system_monitor.py:probe():223] {'os': 'Windows-10-10.0.22621-SP0', 'python': '3.9.13', 'heartbeatAt': '2024-03-25T13:31:49.249316', 'startedAt': '2024-03-25T13:31:46.783851', 'docker': None, 'cuda': None, 'args': (), 'state': 'running', 'program': 'c:\\Shaurya\\Longformer2\\LongformerCoLA\\src\\trainmodel.py', 'codePathLocal': 'LongformerCoLA\\src\\trainmodel.py', 'codePath': 'LongformerCoLA\\src\\trainmodel.py', 'git': {'remote': 'https://github.com/Wackyjac/mrmlongformer2.git', 'commit': '3f7edf9bff6e70b137c959e3fd1d91a249482156'}, 'email': '140714862+Wackyjac@users.noreply.github.com', 'root': 'C:/Shaurya/Longformer2', 'host': 'MSI', 'username': 'Shaurya', 'executable': 'C:\\Users\\Shaurya\\AppData\\Local\\Programs\\Python\\Python39\\python.exe', 'cpu_count': 8, 'cpu_count_logical': 16, 'cpu_freq': {'current': 2304.0, 'min': 0.0, 'max': 2304.0}, 'cpu_freq_per_core': [{'current': 2304.0, 'min': 0.0, 'max': 2304.0}], 'disk': {'/': {'total': 456.09569931030273, 'used': 353.6638717651367}}, 'gpu': 'NVIDIA GeForce RTX 3050 Laptop GPU', 'gpu_count': 1, 'gpu_devices': [{'name': 'NVIDIA GeForce RTX 3050 Laptop GPU', 'memory_total': 4294967296}], 'memory': {'total': 15.708507537841797}}
2024-03-25 19:01:49,376 INFO    HandlerThread:25780 [system_monitor.py:probe():224] Finished collecting system info
2024-03-25 19:01:49,376 INFO    HandlerThread:25780 [system_monitor.py:probe():227] Publishing system info
2024-03-25 19:01:49,377 INFO    HandlerThread:25780 [system_monitor.py:probe():229] Finished publishing system info
2024-03-25 19:01:49,390 DEBUG   SenderThread:25780 [sender.py:send():378] send: files
2024-03-25 19:01:49,390 INFO    SenderThread:25780 [sender.py:_save_file():1365] saving file wandb-metadata.json with policy now
2024-03-25 19:01:49,475 DEBUG   HandlerThread:25780 [handler.py:handle_request():146] handle_request: python_packages
2024-03-25 19:01:49,476 DEBUG   SenderThread:25780 [sender.py:send_request():405] send_request: python_packages
2024-03-25 19:01:49,476 DEBUG   HandlerThread:25780 [handler.py:handle_request():146] handle_request: stop_status
2024-03-25 19:01:49,477 DEBUG   HandlerThread:25780 [handler.py:handle_request():146] handle_request: internal_messages
2024-03-25 19:01:49,478 DEBUG   SenderThread:25780 [sender.py:send_request():405] send_request: stop_status
2024-03-25 19:01:49,840 INFO    Thread-16 :25780 [dir_watcher.py:_on_file_created():271] file/dir created: C:\Shaurya\Longformer2\wandb\run-20240325_190146-bw3hnclm\files\wandb-metadata.json
2024-03-25 19:01:49,841 INFO    Thread-16 :25780 [dir_watcher.py:_on_file_created():271] file/dir created: C:\Shaurya\Longformer2\wandb\run-20240325_190146-bw3hnclm\files\requirements.txt
2024-03-25 19:01:49,908 DEBUG   SenderThread:25780 [sender.py:send():378] send: telemetry
2024-03-25 19:01:50,584 INFO    wandb-upload_0:25780 [upload_job.py:push():131] Uploaded file C:\Users\Shaurya\AppData\Local\Temp\tmprpbmwhq7wandb\rr52i4dw-wandb-metadata.json
2024-03-25 19:01:51,924 DEBUG   HandlerThread:25780 [handler.py:handle_request():146] handle_request: status_report
2024-03-25 19:01:56,950 DEBUG   HandlerThread:25780 [handler.py:handle_request():146] handle_request: status_report
2024-03-25 19:02:01,973 DEBUG   HandlerThread:25780 [handler.py:handle_request():146] handle_request: status_report
2024-03-25 19:02:04,477 DEBUG   HandlerThread:25780 [handler.py:handle_request():146] handle_request: stop_status
2024-03-25 19:02:04,477 DEBUG   SenderThread:25780 [sender.py:send_request():405] send_request: stop_status
2024-03-25 19:02:04,493 DEBUG   HandlerThread:25780 [handler.py:handle_request():146] handle_request: internal_messages
2024-03-25 19:02:07,871 DEBUG   HandlerThread:25780 [handler.py:handle_request():146] handle_request: status_report
2024-03-25 19:02:12,917 DEBUG   HandlerThread:25780 [handler.py:handle_request():146] handle_request: status_report
2024-03-25 19:02:17,969 DEBUG   HandlerThread:25780 [handler.py:handle_request():146] handle_request: status_report
2024-03-25 19:02:19,500 DEBUG   HandlerThread:25780 [handler.py:handle_request():146] handle_request: stop_status
2024-03-25 19:02:19,502 DEBUG   HandlerThread:25780 [handler.py:handle_request():146] handle_request: internal_messages
2024-03-25 19:02:24,524 DEBUG   HandlerThread:25780 [handler.py:handle_request():146] handle_request: keepalive
2024-03-25 19:02:29,560 DEBUG   HandlerThread:25780 [handler.py:handle_request():146] handle_request: keepalive
2024-03-25 19:02:34,509 DEBUG   HandlerThread:25780 [handler.py:handle_request():146] handle_request: internal_messages
2024-03-25 19:02:39,657 DEBUG   HandlerThread:25780 [handler.py:handle_request():146] handle_request: keepalive
2024-03-25 19:02:39,750 WARNING FileStreamThread:25780 [file_stream.py:request_with_retry():668] requests_with_retry encountered retryable exception: HTTPSConnectionPool(host='api.wandb.ai', port=443): Max retries exceeded with url: /files/shaurya24/SandwichFormer%20-%20CoLA/bw3hnclm/file_stream (Caused by NewConnectionError('<urllib3.connection.HTTPSConnection object at 0x00000170629622B0>: Failed to establish a new connection: [WinError 10060] A connection attempt failed because the connected party did not properly respond after a period of time, or established connection failed because connected host has failed to respond')). func: functools.partial(<bound method Session.post of <requests.sessions.Session object at 0x00000170618D30D0>>, timeout=180.0), args: ('https://api.wandb.ai/files/shaurya24/SandwichFormer - CoLA/bw3hnclm/file_stream',), kwargs: {'json': {'complete': False, 'failed': False, 'dropped': 0, 'uploaded': ['wandb-metadata.json']}}
2024-03-25 19:02:41,373 INFO    SenderThread:25780 [retry.py:__call__():172] Retry attempt failed:
Traceback (most recent call last):
  File "C:\Users\Shaurya\AppData\Local\Programs\Python\Python39\lib\site-packages\urllib3\connection.py", line 198, in _new_conn
    sock = connection.create_connection(
  File "C:\Users\Shaurya\AppData\Local\Programs\Python\Python39\lib\site-packages\urllib3\util\connection.py", line 60, in create_connection
    for res in socket.getaddrinfo(host, port, family, socket.SOCK_STREAM):
  File "C:\Users\Shaurya\AppData\Local\Programs\Python\Python39\lib\socket.py", line 954, in getaddrinfo
    for res in _socket.getaddrinfo(host, port, family, type, proto, flags):
socket.gaierror: [Errno 11001] getaddrinfo failed

The above exception was the direct cause of the following exception:

Traceback (most recent call last):
  File "C:\Users\Shaurya\AppData\Local\Programs\Python\Python39\lib\site-packages\urllib3\connectionpool.py", line 793, in urlopen
    response = self._make_request(
  File "C:\Users\Shaurya\AppData\Local\Programs\Python\Python39\lib\site-packages\urllib3\connectionpool.py", line 491, in _make_request
    raise new_e
  File "C:\Users\Shaurya\AppData\Local\Programs\Python\Python39\lib\site-packages\urllib3\connectionpool.py", line 467, in _make_request
    self._validate_conn(conn)
  File "C:\Users\Shaurya\AppData\Local\Programs\Python\Python39\lib\site-packages\urllib3\connectionpool.py", line 1099, in _validate_conn
    conn.connect()
  File "C:\Users\Shaurya\AppData\Local\Programs\Python\Python39\lib\site-packages\urllib3\connection.py", line 616, in connect
    self.sock = sock = self._new_conn()
  File "C:\Users\Shaurya\AppData\Local\Programs\Python\Python39\lib\site-packages\urllib3\connection.py", line 205, in _new_conn
    raise NameResolutionError(self.host, self, e) from e
urllib3.exceptions.NameResolutionError: <urllib3.connection.HTTPSConnection object at 0x00000170629331F0>: Failed to resolve 'api.wandb.ai' ([Errno 11001] getaddrinfo failed)

The above exception was the direct cause of the following exception:

Traceback (most recent call last):
  File "C:\Users\Shaurya\AppData\Local\Programs\Python\Python39\lib\site-packages\requests\adapters.py", line 486, in send
    resp = conn.urlopen(
  File "C:\Users\Shaurya\AppData\Local\Programs\Python\Python39\lib\site-packages\urllib3\connectionpool.py", line 847, in urlopen
    retries = retries.increment(
  File "C:\Users\Shaurya\AppData\Local\Programs\Python\Python39\lib\site-packages\urllib3\util\retry.py", line 515, in increment
    raise MaxRetryError(_pool, url, reason) from reason  # type: ignore[arg-type]
urllib3.exceptions.MaxRetryError: HTTPSConnectionPool(host='api.wandb.ai', port=443): Max retries exceeded with url: /graphql (Caused by NameResolutionError("<urllib3.connection.HTTPSConnection object at 0x00000170629331F0>: Failed to resolve 'api.wandb.ai' ([Errno 11001] getaddrinfo failed)"))

During handling of the above exception, another exception occurred:

Traceback (most recent call last):
  File "C:\Users\Shaurya\AppData\Local\Programs\Python\Python39\lib\site-packages\wandb\sdk\lib\retry.py", line 131, in __call__
    result = self._call_fn(*args, **kwargs)
  File "C:\Users\Shaurya\AppData\Local\Programs\Python\Python39\lib\site-packages\wandb\sdk\internal\internal_api.py", line 369, in execute
    return self.client.execute(*args, **kwargs)  # type: ignore
  File "C:\Users\Shaurya\AppData\Local\Programs\Python\Python39\lib\site-packages\wandb\vendor\gql-0.2.0\wandb_gql\client.py", line 52, in execute
    result = self._get_result(document, *args, **kwargs)
  File "C:\Users\Shaurya\AppData\Local\Programs\Python\Python39\lib\site-packages\wandb\vendor\gql-0.2.0\wandb_gql\client.py", line 60, in _get_result
    return self.transport.execute(document, *args, **kwargs)
  File "C:\Users\Shaurya\AppData\Local\Programs\Python\Python39\lib\site-packages\wandb\sdk\lib\gql_request.py", line 58, in execute
    request = self.session.post(self.url, **post_args)
  File "C:\Users\Shaurya\AppData\Local\Programs\Python\Python39\lib\site-packages\requests\sessions.py", line 637, in post
    return self.request("POST", url, data=data, json=json, **kwargs)
  File "C:\Users\Shaurya\AppData\Local\Programs\Python\Python39\lib\site-packages\requests\sessions.py", line 589, in request
    resp = self.send(prep, **send_kwargs)
  File "C:\Users\Shaurya\AppData\Local\Programs\Python\Python39\lib\site-packages\requests\sessions.py", line 703, in send
    r = adapter.send(request, **kwargs)
  File "C:\Users\Shaurya\AppData\Local\Programs\Python\Python39\lib\site-packages\requests\adapters.py", line 519, in send
    raise ConnectionError(e, request=request)
requests.exceptions.ConnectionError: HTTPSConnectionPool(host='api.wandb.ai', port=443): Max retries exceeded with url: /graphql (Caused by NameResolutionError("<urllib3.connection.HTTPSConnection object at 0x00000170629331F0>: Failed to resolve 'api.wandb.ai' ([Errno 11001] getaddrinfo failed)"))
2024-03-25 19:02:41,801 WARNING FileStreamThread:25780 [file_stream.py:request_with_retry():668] requests_with_retry encountered retryable exception: HTTPSConnectionPool(host='api.wandb.ai', port=443): Max retries exceeded with url: /files/shaurya24/SandwichFormer%20-%20CoLA/bw3hnclm/file_stream (Caused by NameResolutionError("<urllib3.connection.HTTPSConnection object at 0x000001706293D400>: Failed to resolve 'api.wandb.ai' ([Errno 11001] getaddrinfo failed)")). func: functools.partial(<bound method Session.post of <requests.sessions.Session object at 0x00000170618D30D0>>, timeout=180.0), args: ('https://api.wandb.ai/files/shaurya24/SandwichFormer - CoLA/bw3hnclm/file_stream',), kwargs: {'json': {'complete': False, 'failed': False, 'dropped': 0, 'uploaded': ['wandb-metadata.json']}}
2024-03-25 19:02:44,709 DEBUG   HandlerThread:25780 [handler.py:handle_request():146] handle_request: keepalive
2024-03-25 19:02:44,929 ERROR   gpu       :25780 [interfaces.py:monitor():144] Failed to sample metric: No data
2024-03-25 19:02:44,937 ERROR   gpu       :25780 [interfaces.py:monitor():144] Failed to sample metric: No data
2024-03-25 19:02:46,403 WARNING FileStreamThread:25780 [file_stream.py:request_with_retry():668] requests_with_retry encountered retryable exception: HTTPSConnectionPool(host='api.wandb.ai', port=443): Max retries exceeded with url: /files/shaurya24/SandwichFormer%20-%20CoLA/bw3hnclm/file_stream (Caused by NameResolutionError("<urllib3.connection.HTTPSConnection object at 0x0000017062AD4340>: Failed to resolve 'api.wandb.ai' ([Errno 11001] getaddrinfo failed)")). func: functools.partial(<bound method Session.post of <requests.sessions.Session object at 0x00000170618D30D0>>, timeout=180.0), args: ('https://api.wandb.ai/files/shaurya24/SandwichFormer - CoLA/bw3hnclm/file_stream',), kwargs: {'json': {'complete': False, 'failed': False, 'dropped': 0, 'uploaded': ['wandb-metadata.json']}}
2024-03-25 19:02:49,279 DEBUG   SystemMonitor:25780 [system_monitor.py:_start():172] Starting system metrics aggregation loop
2024-03-25 19:02:49,515 DEBUG   HandlerThread:25780 [handler.py:handle_request():146] handle_request: internal_messages
2024-03-25 19:02:54,791 DEBUG   HandlerThread:25780 [handler.py:handle_request():146] handle_request: keepalive
2024-03-25 19:02:54,923 WARNING FileStreamThread:25780 [file_stream.py:request_with_retry():668] requests_with_retry encountered retryable exception: HTTPSConnectionPool(host='api.wandb.ai', port=443): Max retries exceeded with url: /files/shaurya24/SandwichFormer%20-%20CoLA/bw3hnclm/file_stream (Caused by NameResolutionError("<urllib3.connection.HTTPSConnection object at 0x0000017062933C70>: Failed to resolve 'api.wandb.ai' ([Errno 11001] getaddrinfo failed)")). func: functools.partial(<bound method Session.post of <requests.sessions.Session object at 0x00000170618D30D0>>, timeout=180.0), args: ('https://api.wandb.ai/files/shaurya24/SandwichFormer - CoLA/bw3hnclm/file_stream',), kwargs: {'json': {'complete': False, 'failed': False, 'dropped': 0, 'uploaded': ['wandb-metadata.json']}}
2024-03-25 19:02:59,849 DEBUG   HandlerThread:25780 [handler.py:handle_request():146] handle_request: keepalive
2024-03-25 19:03:04,506 DEBUG   HandlerThread:25780 [handler.py:handle_request():146] handle_request: internal_messages
2024-03-25 19:03:09,976 DEBUG   HandlerThread:25780 [handler.py:handle_request():146] handle_request: keepalive
2024-03-25 19:03:12,648 WARNING FileStreamThread:25780 [file_stream.py:request_with_retry():668] requests_with_retry encountered retryable exception: HTTPSConnectionPool(host='api.wandb.ai', port=443): Max retries exceeded with url: /files/shaurya24/SandwichFormer%20-%20CoLA/bw3hnclm/file_stream (Caused by NameResolutionError("<urllib3.connection.HTTPSConnection object at 0x0000017062AD45E0>: Failed to resolve 'api.wandb.ai' ([Errno 11001] getaddrinfo failed)")). func: functools.partial(<bound method Session.post of <requests.sessions.Session object at 0x00000170618D30D0>>, timeout=180.0), args: ('https://api.wandb.ai/files/shaurya24/SandwichFormer - CoLA/bw3hnclm/file_stream',), kwargs: {'json': {'complete': False, 'failed': False, 'dropped': 0, 'uploaded': ['wandb-metadata.json']}}
2024-03-25 19:03:15,042 DEBUG   HandlerThread:25780 [handler.py:handle_request():146] handle_request: keepalive
2024-03-25 19:03:19,512 DEBUG   HandlerThread:25780 [handler.py:handle_request():146] handle_request: internal_messages
2024-03-25 19:03:25,123 DEBUG   HandlerThread:25780 [handler.py:handle_request():146] handle_request: keepalive
2024-03-25 19:03:30,155 DEBUG   HandlerThread:25780 [handler.py:handle_request():146] handle_request: keepalive
2024-03-25 19:03:34,518 DEBUG   HandlerThread:25780 [handler.py:handle_request():146] handle_request: internal_messages
2024-03-25 19:03:40,235 DEBUG   HandlerThread:25780 [handler.py:handle_request():146] handle_request: keepalive
2024-03-25 19:03:45,280 DEBUG   HandlerThread:25780 [handler.py:handle_request():146] handle_request: keepalive
2024-03-25 19:03:49,134 WARNING FileStreamThread:25780 [file_stream.py:request_with_retry():668] requests_with_retry encountered retryable exception: HTTPSConnectionPool(host='api.wandb.ai', port=443): Max retries exceeded with url: /files/shaurya24/SandwichFormer%20-%20CoLA/bw3hnclm/file_stream (Caused by NameResolutionError("<urllib3.connection.HTTPSConnection object at 0x0000017062AE41C0>: Failed to resolve 'api.wandb.ai' ([Errno 11001] getaddrinfo failed)")). func: functools.partial(<bound method Session.post of <requests.sessions.Session object at 0x00000170618D30D0>>, timeout=180.0), args: ('https://api.wandb.ai/files/shaurya24/SandwichFormer - CoLA/bw3hnclm/file_stream',), kwargs: {'json': {'complete': False, 'failed': False, 'dropped': 0, 'uploaded': ['wandb-metadata.json']}}
2024-03-25 19:03:49,546 DEBUG   HandlerThread:25780 [handler.py:handle_request():146] handle_request: internal_messages
2024-03-25 19:03:50,615 DEBUG   HandlerThread:25780 [handler.py:handle_request():146] handle_request: poll_exit
2024-03-25 19:03:55,663 DEBUG   HandlerThread:25780 [handler.py:handle_request():146] handle_request: keepalive
2024-03-25 19:04:00,715 DEBUG   HandlerThread:25780 [handler.py:handle_request():146] handle_request: keepalive
2024-03-25 19:04:05,753 DEBUG   HandlerThread:25780 [handler.py:handle_request():146] handle_request: keepalive
2024-03-25 19:04:10,801 DEBUG   HandlerThread:25780 [handler.py:handle_request():146] handle_request: keepalive
2024-03-25 19:04:15,831 DEBUG   HandlerThread:25780 [handler.py:handle_request():146] handle_request: keepalive
2024-03-25 19:04:20,861 DEBUG   HandlerThread:25780 [handler.py:handle_request():146] handle_request: keepalive
2024-03-25 19:04:25,897 DEBUG   HandlerThread:25780 [handler.py:handle_request():146] handle_request: keepalive
