2024-03-25 19:05:00,813 INFO    StreamThr :27848 [internal.py:wandb_internal():86] W&B internal server running at pid: 27848, started at: 2024-03-25 19:05:00.813765
2024-03-25 19:05:00,815 DEBUG   HandlerThread:27848 [handler.py:handle_request():146] handle_request: status
2024-03-25 19:05:00,819 INFO    WriterThread:27848 [datastore.py:open_for_write():87] open: C:\Shaurya\Longformer2\wandb\run-20240325_190500-hgyh88ae\run-hgyh88ae.wandb
2024-03-25 19:05:00,819 DEBUG   SenderThread:27848 [sender.py:send():378] send: header
2024-03-25 19:05:00,865 DEBUG   SenderThread:27848 [sender.py:send():378] send: run
2024-03-25 19:05:04,118 INFO    SenderThread:27848 [retry.py:__call__():172] Retry attempt failed:
Traceback (most recent call last):
  File "C:\Users\Shaurya\AppData\Local\Programs\Python\Python39\lib\site-packages\urllib3\connection.py", line 198, in _new_conn
    sock = connection.create_connection(
  File "C:\Users\Shaurya\AppData\Local\Programs\Python\Python39\lib\site-packages\urllib3\util\connection.py", line 60, in create_connection
    for res in socket.getaddrinfo(host, port, family, socket.SOCK_STREAM):
  File "C:\Users\Shaurya\AppData\Local\Programs\Python\Python39\lib\socket.py", line 954, in getaddrinfo
    for res in _socket.getaddrinfo(host, port, family, type, proto, flags):
socket.gaierror: [Errno 11001] getaddrinfo failed

The above exception was the direct cause of the following exception:

Traceback (most recent call last):
  File "C:\Users\Shaurya\AppData\Local\Programs\Python\Python39\lib\site-packages\urllib3\connectionpool.py", line 793, in urlopen
    response = self._make_request(
  File "C:\Users\Shaurya\AppData\Local\Programs\Python\Python39\lib\site-packages\urllib3\connectionpool.py", line 491, in _make_request
    raise new_e
  File "C:\Users\Shaurya\AppData\Local\Programs\Python\Python39\lib\site-packages\urllib3\connectionpool.py", line 467, in _make_request
    self._validate_conn(conn)
  File "C:\Users\Shaurya\AppData\Local\Programs\Python\Python39\lib\site-packages\urllib3\connectionpool.py", line 1099, in _validate_conn
    conn.connect()
  File "C:\Users\Shaurya\AppData\Local\Programs\Python\Python39\lib\site-packages\urllib3\connection.py", line 616, in connect
    self.sock = sock = self._new_conn()
  File "C:\Users\Shaurya\AppData\Local\Programs\Python\Python39\lib\site-packages\urllib3\connection.py", line 205, in _new_conn
    raise NameResolutionError(self.host, self, e) from e
urllib3.exceptions.NameResolutionError: <urllib3.connection.HTTPSConnection object at 0x00000204093D5DC0>: Failed to resolve 'api.wandb.ai' ([Errno 11001] getaddrinfo failed)

The above exception was the direct cause of the following exception:

Traceback (most recent call last):
  File "C:\Users\Shaurya\AppData\Local\Programs\Python\Python39\lib\site-packages\requests\adapters.py", line 486, in send
    resp = conn.urlopen(
  File "C:\Users\Shaurya\AppData\Local\Programs\Python\Python39\lib\site-packages\urllib3\connectionpool.py", line 847, in urlopen
    retries = retries.increment(
  File "C:\Users\Shaurya\AppData\Local\Programs\Python\Python39\lib\site-packages\urllib3\util\retry.py", line 515, in increment
    raise MaxRetryError(_pool, url, reason) from reason  # type: ignore[arg-type]
urllib3.exceptions.MaxRetryError: HTTPSConnectionPool(host='api.wandb.ai', port=443): Max retries exceeded with url: /graphql (Caused by NameResolutionError("<urllib3.connection.HTTPSConnection object at 0x00000204093D5DC0>: Failed to resolve 'api.wandb.ai' ([Errno 11001] getaddrinfo failed)"))

During handling of the above exception, another exception occurred:

Traceback (most recent call last):
  File "C:\Users\Shaurya\AppData\Local\Programs\Python\Python39\lib\site-packages\wandb\sdk\lib\retry.py", line 131, in __call__
    result = self._call_fn(*args, **kwargs)
  File "C:\Users\Shaurya\AppData\Local\Programs\Python\Python39\lib\site-packages\wandb\sdk\internal\internal_api.py", line 369, in execute
    return self.client.execute(*args, **kwargs)  # type: ignore
  File "C:\Users\Shaurya\AppData\Local\Programs\Python\Python39\lib\site-packages\wandb\vendor\gql-0.2.0\wandb_gql\client.py", line 52, in execute
    result = self._get_result(document, *args, **kwargs)
  File "C:\Users\Shaurya\AppData\Local\Programs\Python\Python39\lib\site-packages\wandb\vendor\gql-0.2.0\wandb_gql\client.py", line 60, in _get_result
    return self.transport.execute(document, *args, **kwargs)
  File "C:\Users\Shaurya\AppData\Local\Programs\Python\Python39\lib\site-packages\wandb\sdk\lib\gql_request.py", line 58, in execute
    request = self.session.post(self.url, **post_args)
  File "C:\Users\Shaurya\AppData\Local\Programs\Python\Python39\lib\site-packages\requests\sessions.py", line 637, in post
    return self.request("POST", url, data=data, json=json, **kwargs)
  File "C:\Users\Shaurya\AppData\Local\Programs\Python\Python39\lib\site-packages\requests\sessions.py", line 589, in request
    resp = self.send(prep, **send_kwargs)
  File "C:\Users\Shaurya\AppData\Local\Programs\Python\Python39\lib\site-packages\requests\sessions.py", line 703, in send
    r = adapter.send(request, **kwargs)
  File "C:\Users\Shaurya\AppData\Local\Programs\Python\Python39\lib\site-packages\requests\adapters.py", line 519, in send
    raise ConnectionError(e, request=request)
requests.exceptions.ConnectionError: HTTPSConnectionPool(host='api.wandb.ai', port=443): Max retries exceeded with url: /graphql (Caused by NameResolutionError("<urllib3.connection.HTTPSConnection object at 0x00000204093D5DC0>: Failed to resolve 'api.wandb.ai' ([Errno 11001] getaddrinfo failed)"))
2024-03-25 19:05:05,910 DEBUG   HandlerThread:27848 [handler.py:handle_request():146] handle_request: keepalive
2024-03-25 19:05:10,949 DEBUG   HandlerThread:27848 [handler.py:handle_request():146] handle_request: keepalive
2024-03-25 19:05:15,984 DEBUG   HandlerThread:27848 [handler.py:handle_request():146] handle_request: keepalive
2024-03-25 19:05:21,029 DEBUG   HandlerThread:27848 [handler.py:handle_request():146] handle_request: keepalive
2024-03-25 19:05:26,072 DEBUG   HandlerThread:27848 [handler.py:handle_request():146] handle_request: keepalive
2024-03-25 19:05:31,118 DEBUG   HandlerThread:27848 [handler.py:handle_request():146] handle_request: keepalive
2024-03-25 19:05:36,171 DEBUG   HandlerThread:27848 [handler.py:handle_request():146] handle_request: keepalive
2024-03-25 19:05:41,219 DEBUG   HandlerThread:27848 [handler.py:handle_request():146] handle_request: keepalive
2024-03-25 19:05:46,258 DEBUG   HandlerThread:27848 [handler.py:handle_request():146] handle_request: keepalive
2024-03-25 19:05:51,306 DEBUG   HandlerThread:27848 [handler.py:handle_request():146] handle_request: keepalive
2024-03-25 19:05:56,352 DEBUG   HandlerThread:27848 [handler.py:handle_request():146] handle_request: keepalive
2024-03-25 19:06:01,398 DEBUG   HandlerThread:27848 [handler.py:handle_request():146] handle_request: keepalive
2024-03-25 19:06:06,441 DEBUG   HandlerThread:27848 [handler.py:handle_request():146] handle_request: keepalive
2024-03-25 19:06:11,486 DEBUG   HandlerThread:27848 [handler.py:handle_request():146] handle_request: keepalive
2024-03-25 19:06:16,539 DEBUG   HandlerThread:27848 [handler.py:handle_request():146] handle_request: keepalive
2024-03-25 19:06:21,593 DEBUG   HandlerThread:27848 [handler.py:handle_request():146] handle_request: keepalive
2024-03-25 19:06:26,636 DEBUG   HandlerThread:27848 [handler.py:handle_request():146] handle_request: keepalive
2024-03-25 19:06:31,677 DEBUG   HandlerThread:27848 [handler.py:handle_request():146] handle_request: cancel
2024-03-25 19:06:31,677 DEBUG   HandlerThread:27848 [handler.py:handle_request():146] handle_request: cancel
2024-03-25 19:06:31,677 DEBUG   SenderThread:27848 [sender.py:send():387] Record cancelled: run
2024-03-25 19:06:31,678 DEBUG   HandlerThread:27848 [handler.py:handle_request():146] handle_request: status_report
2024-03-25 19:06:32,095 DEBUG   HandlerThread:27848 [handler.py:handle_request():146] handle_request: shutdown
2024-03-25 19:06:32,095 INFO    HandlerThread:27848 [handler.py:finish():869] shutting down handler
2024-03-25 19:06:32,682 INFO    SenderThread:27848 [sender.py:finish():1521] shutting down sender
2024-03-25 19:06:32,682 INFO    WriterThread:27848 [datastore.py:close():296] close: C:\Shaurya\Longformer2\wandb\run-20240325_190500-hgyh88ae\run-hgyh88ae.wandb
